<?xml version="1.0" ?>
<robot name="my_robot">

<!--JOINTS-->

  <joint name="my_robot__link_0_JOINT_0" type="fixed">
    <parent link="my_robot__link_0"/>
    <child link="my_robot__link_1_clone_1"/>
    <origin rpy="0  0  0" xyz="-0.24    -0.24     0.03259"/>
    <axis xyz="0  0  0"/>
    <limit effort="0" lower="0" upper="0" velocity="0"/>
  </joint>
  <joint name="my_robot__link_0_JOINT_14" type="fixed"> <!--caster wheel 1-->
    <parent link="my_robot__link_0"/>
    <child link="my_robot__link_10"/>
    <origin rpy="0  0  0" xyz="0.212   0     -0.0792"/>
    <axis xyz="0  0  0"/>
    <limit effort="0" lower="0" upper="0" velocity="0"/>
  </joint>
  <joint name="my_robot__link_0_JOINT_15" type="fixed"> <!--caster wheel 2-->
    <parent link="my_robot__link_0"/>
    <child link="my_robot__link_10_clone"/>
    <origin rpy="0  0  0" xyz="-0.212   0     -0.0792"/>
    <axis xyz="0  0  0"/>
    <limit effort="0" lower="0" upper="0" velocity="0"/>
  </joint>
  <joint name="my_robot__link_0_JOINT_1" type="fixed">
    <parent link="my_robot__link_0"/>
    <child link="my_robot__link_1_clone"/>
    <origin rpy="0  0  0" xyz="-0.24     0.24     0.03259"/>
    <axis xyz="0  0  0"/>
    <limit effort="0" lower="0" upper="0" velocity="0"/>
  </joint>
  <joint name="my_robot__link_0_JOINT_2" type="fixed">
    <parent link="my_robot__link_0"/>
    <child link="my_robot__link_1_clone_0"/>
    <origin rpy="0  0  0" xyz="0.24    -0.24     0.03259"/>
    <axis xyz="0  0  0"/>
    <limit effort="0" lower="0" upper="0" velocity="0"/>
  </joint>
  <joint name="my_robot__link_0_JOINT_3" type="fixed">
    <parent link="my_robot__link_0"/>
    <child link="my_robot__link_1"/>
    <origin rpy="0  0  0" xyz="0.24     0.24     0.03259"/>
    <axis xyz="0  0  0"/>
    <limit effort="0" lower="0" upper="0" velocity="0"/>
  </joint>
  <joint name="my_robot__link_0_JOINT_6" type="continuous"> <!--Side Wheel L-->
    <parent link="my_robot__link_0"/>
    <child link="my_robot__link_3"/>
    <origin rpy="1.5707  0      0" xyz="0      -0.275   -0.01739"/>
    <axis xyz="0   0   1"/>
    <limit effort="1000"  velocity="1000"/>
    <dynamics damping="1.0" friction="1.0"/>
  </joint>
  <joint name="my_robot__link_0_JOINT_7" type="continuous"> <!--Side Wheel R-->
    <parent link="my_robot__link_0"/>
    <child link="my_robot__link_3_clone"/>
    <origin rpy="1.5707  0      0" xyz="0       0.275   -0.01739"/>
    <axis xyz="0 0 1"/>
    <limit effort="1000" velocity="1000"/>
    <dynamics damping="1.0" friction="1.0"/>
  </joint>
  <joint name="my_robot__link_1_JOINT_5" type="fixed">
    <parent link="my_robot__link_1"/>
    <child link="my_robot__link_0_clone"/>
    <origin rpy="0  0  0" xyz="-0.24 -0.24  0.05"/>
    <axis xyz="0  0  0"/>
    <limit effort="0" lower="0" upper="0" velocity="0"/>
  </joint>
  <joint name="camera_joint" type="fixed">  <!--Defined Camera Joint-->
    <parent link="my_robot__link_0_clone"/>
    <child link="camera"/>
    <origin rpy="0  0  3.14" xyz="-0.275  0   0.0001"/>
    <axis xyz="0  1  0"/>
    <limit effort="0" lower="0" upper="0" velocity="0"/>
  </joint>  
  <joint name="hokuyo_joint" type="fixed"> <!--Defined LIDAR Joint-->
    <parent link="my_robot__link_0_clone"/>
    <child link="hokuyo"/>
    <origin rpy="0  0  0" xyz="-0.150       0    0.06"/>
    <axis xyz="0  1  0"/>
    <limit effort="0" lower="0" upper="0" velocity="0"/>
  </joint>

<!--LINKS-->

  <link name="my_robot__link_0">
    <inertial>
      <mass value="1"/>
      <origin rpy="0  0  0" xyz="0  0  0"/>
      <inertia ixx="0.166667" ixy="0" ixz="0" iyy="0.166667" iyz="0" izz="0.166667"/>
    </inertial>
    <collision name="my_robot__collision">
      <origin rpy="0  0  0" xyz="0       0      -0.01739"/>
      <geometry>
        <box size="0.5 0.5 0.05"/>
      </geometry>
    </collision>
    <visual name="my_robot__visual">
      <origin rpy="0  0  0" xyz="0       0      -0.01739"/>
      <geometry>
        <box size="0.5 0.5 0.05"/>
      </geometry>
    </visual>
  </link>
  <link name="my_robot__link_0_clone">
    <inertial>
      <mass value="1"/>
      <origin rpy="0  0  0" xyz="0  0  0"/>
      <inertia ixx="0.166667" ixy="0" ixz="0" iyy="0.166667" iyz="0" izz="0.166667"/>
    </inertial>
    <collision name="my_robot__collision">
      <origin rpy="0  0  0" xyz="0  0  0"/>
      <geometry>
        <box size="0.5 0.5 0.05"/>
      </geometry>
    </collision>
    <visual name="my_robot__visual">
      <origin rpy="0  0  0" xyz="0  0  0"/>
      <geometry>
        <box size="0.5 0.5 0.05"/>
      </geometry>
    </visual>
  </link>
  <link name="my_robot__link_1">
    <inertial>
      <mass value="1"/>
      <origin rpy="0  0  0" xyz="0  0  0"/>
      <inertia ixx="0.145833" ixy="0" ixz="0" iyy="0.145833" iyz="0" izz="0.125"/>
    </inertial>
    <collision name="my_robot__collision">
      <origin rpy="0  0  0" xyz="0  0  0"/>
      <geometry>
        <cylinder length="0.05" radius="0.01"/>
      </geometry>
    </collision>
    <visual name="my_robot__visual">
      <origin rpy="0  0  0" xyz="0  0  0"/>
      <geometry>
        <cylinder length="0.05" radius="0.01"/>
      </geometry>
    </visual>
  </link>
  <link name="my_robot__link_10"> <!--CASTER WHEEL 1-->
    <inertial>
      <mass value="1"/>
      <origin rpy="0  0  0" xyz="0  0  0"/>
      <inertia ixx="0.1" ixy="0" ixz="0" iyy="0.1" iyz="0" izz="0.1"/>
    </inertial>
    <collision name="my_robot__collision">
      <origin rpy="0  0  0" xyz="0  0  0"/>
      <geometry>
        <sphere radius="0.038"/>
      </geometry>
    </collision>
    <visual name="my_robot__visual">
      <origin rpy="0  0  0" xyz="0  0  0"/>
      <geometry>
        <sphere radius="0.038"/>
      </geometry>
    </visual>
  </link>
  <link name="my_robot__link_10_clone"> <!--CASTER WHEEL 2-->
    <inertial>
      <mass value="1"/>
      <origin rpy="0  0  0" xyz="0  0  0"/>
      <inertia ixx="0.1" ixy="0" ixz="0" iyy="0.1" iyz="0" izz="0.1"/>
    </inertial>
    <collision name="my_robot__collision">
      <origin rpy="0  0  0" xyz="0  0  0"/>
      <geometry>
        <sphere radius="0.038"/>
      </geometry>
    </collision>
    <visual name="my_robot__visual">
      <origin rpy="0  0  0" xyz="0  0  0"/>
      <geometry>
        <sphere radius="0.038"/>
      </geometry>
    </visual>
  </link>
  <link name="my_robot__link_1_clone">
    <inertial>
      <mass value="1"/>
      <origin rpy="0  0  0" xyz="0  0  0"/>
      <inertia ixx="0.145833" ixy="0" ixz="0" iyy="0.145833" iyz="0" izz="0.125"/>
    </inertial>
    <collision name="my_robot__collision">
      <origin rpy="0  0  0" xyz="0  0  0"/>
      <geometry>
        <cylinder length="0.05" radius="0.01"/>
      </geometry>
    </collision>
    <visual name="my_robot__visual">
      <origin rpy="0  0  0" xyz="0  0  0"/>
      <geometry>
        <cylinder length="0.05" radius="0.01"/>
      </geometry>
    </visual>
  </link>
  <link name="my_robot__link_1_clone_0">
    <inertial>
      <mass value="1"/>
      <origin rpy="0  0  0" xyz="0  0  0"/>
      <inertia ixx="0.145833" ixy="0" ixz="0" iyy="0.145833" iyz="0" izz="0.125"/>
    </inertial>
    <collision name="my_robot__collision">
      <origin rpy="0  0  0" xyz="0  0  0"/>
      <geometry>
        <cylinder length="0.05" radius="0.01"/>
      </geometry>
    </collision>
    <visual name="my_robot__visual">
      <origin rpy="0  0  0" xyz="0  0  0"/>
      <geometry>
        <cylinder length="0.05" radius="0.01"/>
      </geometry>
    </visual>
  </link>
  <link name="my_robot__link_1_clone_1">
    <inertial>
      <mass value="1"/>
      <origin rpy="0  0  0" xyz="0  0  0"/>
      <inertia ixx="0.145833" ixy="0" ixz="0" iyy="0.145833" iyz="0" izz="0.125"/>
    </inertial>
    <collision name="my_robot__collision">
      <origin rpy="0  0  0" xyz="0  0  0"/>
      <geometry>
        <cylinder length="0.05" radius="0.01"/>
      </geometry>
    </collision>
    <visual name="my_robot__visual">
      <origin rpy="0  0  0" xyz="0  0  0"/>
      <geometry>
        <cylinder length="0.05" radius="0.01"/>
      </geometry>
    </visual>
  </link>
  <link name="my_robot__link_3">
    <inertial>
      <mass value="1"/>
      <origin rpy="0  0  0" xyz="0  0  0"/>
      <inertia ixx="0.145833" ixy="0" ixz="0" iyy="0.145833" iyz="0" izz="0.125"/>
    </inertial>
    <collision name="my_robot__collision">
      <origin rpy="0  0  0" xyz="0  0  0"/>
      <geometry>
        <cylinder length="0.05" radius="0.1"/>
      </geometry>
    </collision>
    <visual name="my_robot__visual">
      <origin rpy="0  0  0" xyz="0  0  0"/>
      <geometry>
        <cylinder length="0.05" radius="0.1"/>
      </geometry>
    </visual>
  </link>
  <link name="my_robot__link_3_clone">
    <inertial>
      <mass value="1"/>
      <origin rpy="0  0  0" xyz="0  0  0"/>
      <inertia ixx="0.145833" ixy="0" ixz="0" iyy="0.145833" iyz="0" izz="0.125"/>
    </inertial>
    <collision name="my_robot__collision">
      <origin rpy="0  0  0" xyz="0  0  0"/>
      <geometry>
        <cylinder length="0.05" radius="0.1"/>
      </geometry>
    </collision>
    <visual name="my_robot__visual">
      <origin rpy="0  0  0" xyz="0  0  0"/>
      <geometry>
        <cylinder length="0.05" radius="0.1"/>
      </geometry>
    </visual>
  </link>
   <link name="camera">  <!--CAMERA LINK-->
    <inertial>
      <mass value="0.1"/>
      <origin rpy="0  0  0" xyz="0  0  0"/>
      <inertia ixx="1e-6" ixy="0" ixz="0" iyy="1e-6" iyz="0" izz="0.1"/>
    </inertial>
    <collision name="my_robot__collision">
      <origin rpy="0  0  0" xyz="0  0  0"/>
      <geometry>
        <box size="0.05 0.05 0.05"/>
      </geometry>
    </collision>
    <visual name="my_robot__visual">
      <origin rpy="0  0  0" xyz="0  0  0"/>
      <geometry>
        <box size="0.05 0.05 0.05"/>
      </geometry>
    </visual>
  </link>
  <link name="hokuyo">  <!--LIDAR LINK-->
    <inertial>
      <mass value="1e-5"/>
      <origin rpy="0  0  0" xyz="0  0  0"/>
      <inertia ixx="1e-6" ixy="0" ixz="0" iyy="1e-6" iyz="0" izz="0.1"/>
    </inertial>
    <collision name="my_robot__collision">
      <origin rpy="0  0  0" xyz="0  0  0"/>
      <geometry>
        <box size="0.1 0.1 0.1"/>
      </geometry>
    </collision>
    <visual name="my_robot__visual">
      <origin rpy="0  0  0" xyz="0  0  0"/>
      <geometry>
        <mesh filename="package://my_robot/meshes/hokuyo.dae"/>
      </geometry>
    </visual>
  </link>

<!--GAZEBO PLUGINS-->

  <gazebo>
    <plugin name="differential_drive_controller" filename="libgazebo_ros_diff_drive.so">
      <legacyMode>false</legacyMode>
      <alwaysOn>true</alwaysOn>
      <updateRate>10</updateRate>
      <leftJoint>my_robot__link_0_JOINT_6</leftJoint>
      <rightJoint>my_robot__link_0_JOINT_7</rightJoint>
      <wheelSeparation>0.4</wheelSeparation>
      <wheelDiameter>0.2</wheelDiameter>
      <torque>10</torque>
      <commandTopic>cmd_vel</commandTopic>
      <odometryTopic>odom</odometryTopic>
      <odometryFrame>odom</odometryFrame>
      <robotBaseFrame>my_robot__link_0</robotBaseFrame>
      <publishWheelTF>false</publishWheelTF>
      <publishWheelJointState>false</publishWheelJointState>
      <rosDebugLevel>na</rosDebugLevel>
      <wheelAcceleration>0</wheelAcceleration>
      <wheelTorque>5</wheelTorque>
      <odometrySource>world</odometrySource>
      <publishTf>1</publishTf>
      <publishOdomTF>true</publishOdomTF>
    </plugin>
  </gazebo>

  <!-- camera -->
  
  <gazebo reference="camera">
    <sensor type="camera" name="camera1">
      <update_rate>30.0</update_rate>
      <camera name="head">
        <horizontal_fov>1.3962634</horizontal_fov>
        <image>
          <width>800</width>
          <height>800</height>
          <format>R8G8B8</format>
        </image>
        <clip>
          <near>0.02</near>
          <far>300</far>
        </clip>
      </camera>
      <plugin name="camera_controller" filename="libgazebo_ros_camera.so">
        <alwaysOn>true</alwaysOn>
        <updateRate>0.0</updateRate>
        <cameraName>camera</cameraName>
        <imageTopicName>rgb/image_raw</imageTopicName>
        <cameraInfoTopicName>rgb/camera_info</cameraInfoTopicName>
        <frameName>camera</frameName>
        <hackBaseline>0.07</hackBaseline>
        <distortionK1>0.0</distortionK1>
        <distortionK2>0.0</distortionK2>
        <distortionK3>0.0</distortionK3>
        <distortionT1>0.0</distortionT1>
        <distortionT2>0.0</distortionT2>
      </plugin>
    </sensor>
  </gazebo>

  <!-- hokuyo -->
  <gazebo reference="hokuyo">
    <sensor type="ray" name="head_hokuyo_sensor">
      <pose>0 0 0 0 0 0</pose>
      <visualize>false</visualize>
      <update_rate>40</update_rate>
      <ray>
        <scan>
          <horizontal>
            <samples>720</samples>
            <resolution>1</resolution>
            <min_angle>-1.570796</min_angle>
            <max_angle>1.570796</max_angle>
          </horizontal>
        </scan>
        <range>
          <min>0.10</min>
          <max>30.0</max>
          <resolution>0.01</resolution>
        </range>
        <noise>
          <type>gaussian</type>
          <!-- Noise parameters based on published spec for Hokuyo laser
               achieving "+-30mm" accuracy at range < 10m.  A mean of 0.0m and
               stddev of 0.01m will put 99.7% of samples within 0.03m of the true
               reading. -->
          <mean>0.0</mean>
          <stddev>0.01</stddev>
        </noise>
      </ray>
      <plugin name="gazebo_ros_head_hokuyo_controller" filename="libgazebo_ros_laser.so">
        <topicName>/scan</topicName>
        <frameName>hokuyo</frameName>
      </plugin>
    </sensor>
  </gazebo>
</robot>
